Workbook
Name LINK_KIT: INICIO!$B$17

Sheet INICIO
A1: CUENTA VIVA — Calculadora LITE (gratis)
B2: Mantén tu cuenta fondeada viva.
B4: CÓMO USARLA
B5: 1. CONFIG: elige tu firma, balance inicial, fase, riesgo por operación e instrumento.
B6: 2. CALCULADORA: escribe tu equity actual, la referencia de inicio del día y (si es trailing) el pico.
B7: 3. Mira el semáforo: VERDE puedes operar · ÁMBAR reduce riesgo · ROJO detente hoy. Usa el lote sugerido y nunca pases del lote máximo seguro.
B9: Funciona en Excel 2016+ y en Google Sheets (Archivo > Importar). Sin macros.
B11: AVISO
B12: No es asesoría financiera. Las reglas de cada firma cambian: verifica siempre en la web oficial.
B13: Herramienta de control de riesgo. No da señales ni estrategias y no promete pasar ningún challenge. Presets de referencia oct-2026: verifica en la web oficial de tu firma.
B15: ¿QUIERES EL KIT COMPLETO?
B16: El Kit Cuenta Viva suma registro de operaciones, panel automático, estadísticas por setup, comparación 'con checklist vs sin checklist' y reglas por firma. Más información:
B17: https://cognitrade.github.io/cuentaviva/kit.html
B19: Versión v1.0 — octubre 2026

Sheet CONFIG
A1: CONFIG — Configura tu cuenta
B2: Amarillo = lo editas tú. Gris = se calcula solo. No es asesoría financiera. Las reglas de cada firma cambian: verifica siempre en la web oficial.
B4: TU CUENTA
B5: Firma | C5: FTMO 2 fases | D5: Elige tu firma. 'Personalizada' = reglas a mano en 'Tu ajuste'.
B6: Balance inicial de la cuenta (B0) | C6: 100000 | D6: Tamaño de la cuenta, p. ej. 100000.
B7: Fase | C7: Fase 1 | D7: Fase 1 / Fase 2 / Fondeada (fondeada no tiene objetivo).
B8: Riesgo por operación (% del balance inicial) | C8: 0.005 | D8: 0.50% de 100k = 500 USD por operación.
B9: Riesgo por operación en USD (opcional) | D9: Si escribes un monto aquí, manda sobre el %.
B10: Riesgo usado por operación (R$) | C10: =IF(C9="",C8*C6,C9) | D10: Este es tu 'R': lo que pierdes si salta el stop completo.
B11: Instrumento | C11: EURUSD | D11: Define el valor por punto/pip (VPP).
B12: VPP del preset | C12: =INDEX(CONFIG!$B$54:$B$63,MATCH(C11,CONFIG!$A$54:$A$63,0)) | D12: USD por 1 punto/pip con 1 lote. Depende del bróker.
B13: VPP personalizado (opcional) | D13: Si escribes un valor aquí, manda sobre el preset.
B14: VPP usado | C14: =IF(C13="",C12,C13)
B15: Distancia típica del stop (puntos o pips) | C15: 20 | D15: Se usa para el lote sugerido.
B18: Zona horaria: el 'inicio del día' se calcula con la fecha de tu computador (en Google Sheets: Archivo > Configuración > Zona horaria). Si tu firma reinicia el día a otra hora (p. ej. medianoche de Europa), escribe la referencia manual en la CALCULADORA.
B19: REGLAS DE LA FIRMA — preset + tu ajuste
B20: Regla | C20: Preset de la firma | D20: Tu ajuste (opcional) | E20: Valor usado | F20: Nota
B21: Pérdida diaria (%) | C21: =INDEX(CONFIG!$C$41:$C$48,MATCH($C$5,CONFIG!$B$41:$B$48,0)) | E21: =IF(D21="",C21,D21) | F21: Ver 'Base pérdida diaria'.
B22: Base pérdida diaria (inicial / referencia) | C22: =INDEX(CONFIG!$D$41:$D$48,MATCH($C$5,CONFIG!$B$41:$B$48,0)) | E22: =IF(D22="",C22,D22) | F22: inicial: piso = REF − % × B0. referencia: piso = REF × (1 − %).
B23: Pérdida máxima (% del balance inicial) | C23: =INDEX(CONFIG!$E$41:$E$48,MATCH($C$5,CONFIG!$B$41:$B$48,0)) | E23: =IF(D23="",C23,D23) | F23: Estática: piso fijo. Trailing: sube con el pico.
B24: Tipo de pérdida máxima | C24: =INDEX(CONFIG!$F$41:$F$48,MATCH($C$5,CONFIG!$B$41:$B$48,0)) | E24: =IF(D24="",C24,D24) | F24: estática o trailing.
B25: Trailing: ¿el piso deja de subir en B0? | C25: =INDEX(CONFIG!$G$41:$G$48,MATCH($C$5,CONFIG!$B$41:$B$48,0)) | E25: =IF(D25="",C25,D25) | F25: Sí = el piso nunca pasa del balance inicial.
B26: Objetivo Fase 1 (%) | C26: =INDEX(CONFIG!$H$41:$H$48,MATCH($C$5,CONFIG!$B$41:$B$48,0)) | E26: =IF(D26="",C26,D26)
B27: Objetivo Fase 2 (%) | C27: =INDEX(CONFIG!$I$41:$I$48,MATCH($C$5,CONFIG!$B$41:$B$48,0)) | E27: =IF(D27="",C27,D27)
B28: Días mínimos | C28: =INDEX(CONFIG!$J$41:$J$48,MATCH($C$5,CONFIG!$B$41:$B$48,0)) | E28: =IF(D28="",C28,D28)
B29: Tipo de días mínimos (operados / rentables) | C29: =INDEX(CONFIG!$K$41:$K$48,MATCH($C$5,CONFIG!$B$41:$B$48,0)) | E29: =IF(D29="",C29,D29) | F29: rentables = días con PnL cerrado ≥ el umbral de abajo.
B30: Día rentable si PnL del día ≥ (% de B0) | C30: =INDEX(CONFIG!$L$41:$L$48,MATCH($C$5,CONFIG!$B$41:$B$48,0)) | E30: =IF(D30="",C30,D30) | F30: Solo aplica si los días son 'rentables'.
B31: REF: qué escribir como inicio del día | C31: =INDEX(CONFIG!$M$41:$M$48,MATCH($C$5,CONFIG!$B$41:$B$48,0)) | E31: =IF(D31="",C31,D31) | F31: Lo que tu firma usa como referencia diaria.
B32: Reset del día | C32: =INDEX(CONFIG!$N$41:$N$48,MATCH($C$5,CONFIG!$B$41:$B$48,0)) | E32: =IF(D32="",C32,D32) | F32: Hora en que tu firma empieza un día nuevo.
B33: Objetivo usado según la fase | E33: =IF(C7="Fase 1",E26,IF(C7="Fase 2",E27,0)) | F33: Fondeada = sin objetivo.
B35: Valores de referencia oct-2026 — verifica en la web oficial de tu firma.
A38: PRESETS DE FIRMAS (editables)
A39: Valores de referencia oct-2026 — verifica en la web oficial de tu firma. La pérdida máxima siempre es % del balance inicial (B0). La diaria depende de 'Base pérdida diaria': inicial = % de B0; referencia = % de la REF del inicio del día.
A40: id | B40: Nombre (aparece en CONFIG) | C40: Pérdida diaria | D40: Base pérdida diaria | E40: Pérdida máxima | F40: Tipo pérdida máx | G40: Trailing: bloquear en B0 | H40: Objetivo F1 | I40: Objetivo F2 | J40: Días mín | K40: Tipo de días mín | L40: Día rentable ≥ (% B0) | M40: REF: qué escribir | N40: Reset del día
A41: ftmo2 | B41: FTMO 2 fases | C41: 0.05 | D41: inicial | E41: 0.1 | F41: estática | G41: No | H41: 0.1 | I41: 0.05 | J41: 4 | K41: operados | L41: 0 | M41: balance al inicio del día | N41: 00:00 CE(S)T
A42: fn_stellar2 | B42: FundedNext Stellar 2 fases | C42: 0.05 | D42: inicial | E42: 0.1 | F42: estática | G42: No | H42: 0.08 | I42: 0.05 | J42: 5 | K42: operados | L42: 0 | M42: balance al inicio del día (supuesto conservador: si tu equity era mayor, usa el mayor) | N42: 00:00 hora servidor (GMT+2/+3)
A43: the5ers_hs | B43: The5ers High Stakes (New) | C43: 0.05 | D43: referencia | E43: 0.1 | F43: estática | G43: No | H43: 0.1 | I43: 0.05 | J43: 3 | K43: rentables | L43: 0.005 | M43: mayor entre balance y equity al cierre anterior | N43: 00:00 hora servidor
A44: custom | B44: Personalizada | C44: 0.05 | D44: inicial | E44: 0.1 | F44: estática | G44: Sí | H44: 0.1 | I44: 0.05 | J44: 0 | K44: operados | L44: 0 | M44: editable | N44: —
A49: Las filas vacías son para agregar otra firma: escribe el nombre y sus reglas; aparecerá en el selector de CONFIG. The5ers High Stakes 'Classic' usa objetivo F1 de 8%. Ninguno de estos programas tiene trailing ni regla de consistencia por defecto (FundedNext la ofrece como add-on opcional de 40%).
A51: VALOR POR PUNTO / PIP (VPP) — USD por 1 punto o pip con 1 lote estándar
...

Sheet CALCULADORA
A1: CALCULADORA — ¿Puedo operar hoy?
B2: No es asesoría financiera. Las reglas de cada firma cambian: verifica siempre en la web oficial.
B4: =IF(H4="VERDE","VERDE — Puedes operar",IF(H4="ÁMBAR","ÁMBAR — Reduce riesgo",IF(C22<=0,"ROJO — Cuenta violada: detente","ROJO — Detente hoy"))) | H4: =IF(C22<=0,"ROJO",IF(C22<C23,"ROJO",IF(C22<3*C23,"ÁMBAR","VERDE")))
B7: =IF(C20<=C21,"Límite más cercano: pérdida DIARIA — margen "&FIXED(MAX(0,C20),2)&" USD","Límite más cercano: pérdida MÁXIMA — margen "&FIXED(MAX(0,C21),2)&" USD")&" | Verde ≥ 3R · Ámbar entre 1R y 3R · Rojo < 1R"
B9: DATOS DE TU PLATAFORMA (escríbelos tú)
B10: Dato | C10: Valor | D10: Qué escribir
B11: Balance inicial (B0) | C11: =CONFIG!C6 | D11: Se edita en CONFIG.
B12: Equity actual (EQ) | C12: 100000 | D12: Balance + flotante, tal como lo muestra tu plataforma.
B13: Referencia de inicio del día (REF) | C13: 100000 | D13: ="Tu firma usa: "&CONFIG!$E$31&" · reset "&CONFIG!$E$32
B14: Pico de balance/equity (solo trailing) | C14: 100000 | D14: El máximo alcanzado. Si tu cuenta es estática, déjalo igual al B0.
B16: LÍMITES DE HOY
B17: Concepto | C17: Valor | D17: Cómo se calcula
B18: Piso diario | C18: =IF(CONFIG!$E$22="referencia",$C$13*(1-CONFIG!$E$21),$C$13-CONFIG!$E$21*$C$11) | D18: inicial: REF − pérdida diaria × B0 · referencia: REF × (1 − pérdida diaria)
B19: Piso máximo | C19: =IF(CONFIG!$E$24="trailing",IF(CONFIG!$E$25="Sí",MIN($C$14-CONFIG!$E$23*$C$11,$C$11),$C$14-CONFIG!$E$23*$C$11),$C$11*(1-CONFIG!$E$23)) | D19: Estática: B0 × (1 − pérdida máx). Trailing: PICO − pérdida máx × B0
B20: Colchón diario | C20: =$C$12-C18 | D20: EQ − piso diario
B21: Colchón máximo | C21: =$C$12-C19 | D21: EQ − piso máximo
B22: COLCHÓN EFECTIVO | C22: =MIN(C20,C21) | D22: El menor de los dos. Si es ≤ 0, la cuenta está violada.
B23: Riesgo por operación (R$) | C23: =CONFIG!$C$10 | D23: Desde CONFIG
B24: Stops completos que aguantas | C24: =IF(C23>0,IF(C22<=0,0,INT(C22/C23)),"—") | D24: Cuántas pérdidas de 1R seguidas antes de violar
B25: Límite más cercano | C25: =IF(C20<=C21,"Diario","Máximo") | D25: Cuál de los dos pisos tienes más cerca
B27: TAMAÑO DE POSICIÓN
B28: Stop (puntos o pips) | C28: =CONFIG!$C$15 | D28: Desde CONFIG
B29: VPP (USD por punto/pip, 1 lote) | C29: =CONFIG!$C$14 | D29: Desde CONFIG — depende del bróker
B30: LOTE SUGERIDO | C30: =IF(C28*C29>0,ROUNDDOWN(C23/(C28*C29),2),"—") | D30: R$ ÷ (stop × VPP), redondeado hacia abajo a 0.01
B31: Lote máximo seguro | C31: =IF(C28*C29>0,IF(C22<=0,0,ROUNDDOWN(C22/(C28*C29),2)),"—") | D31: Con este lote un stop completo NO viola la cuenta. Nunca lo superes.
B33: PROGRESO
B34: Fase | C34: =CONFIG!$C$7
B35: Objetivo de la fase (%) | C35: =CONFIG!$E$33
B36: Balance objetivo | C36: =IF(C35>0,$C$11*(1+C35),"—")
B37: Progreso al objetivo | C37: =IF(C35>0,MAX(0,($C$12-$C$11)/(C35*$C$11)),"—")
